Workbook

Sheet what is covariance
B1: CRIME_RATE | C1: AGE %(<1940) | D1: INDUSTRY | E1: NOX (ppm) | F1: DISTANCE FROM HW (MILES)
A2: CRIME_RATE | B2: =VARP(data!$A$2:$A$507) -> 8.5126347
A3: AGE %(<1940) | B3: 0.0057638814 | C3: =VARP(data!$B$2:$B$507) -> 0.079079247
A4: INDUSTRY | B4: -0.074977837 | C4: 1.2426783 | D4: =VARP(data!$C$2:$C$507) -> 46.97143
A5: NOX (ppm) | B5: 0.00069195644 | C5: 0.023812119 | D5: 0.60587394 | E5: =VARP(data!$D$2:$D$507) -> 0.013401099
A6: DISTANCE FROM HW (MILES) | B6: -0.19573044 | C6: 1.1154996 | D6: 35.479714 | E6: 0.61571022 | F6: =VARP(data!$E$2:$E$507) -> 75.666531
B9: note- rendu same column intersect agara place ku "symmetrical values " nu name , adhuku aprm vara vendiya covariance values ellame keela likewise repeat aagu so that paaka clumsy ah irukum nu adhu empty cell ah varum . Ippo crime rate la industry covariance thedradhu onnu dha , industry la crime rate thedradhu onnu dha. )
B11: Var 1 | C11: Var 2 | D11: Var 3 | E11: Var 4 | F11: Var 5
B12: Var 1 | C12: Var(V1) | D12: Cov(V1,V2) | E12: Cov(V1,V3) | F12: Cov(V1,V4) | G12: Cov(V1,V5)
B13: Var 2 | C13: Cov(V2,V1) | D13: Var(V2) | E13: Cov(V2,V3) | F13: Cov(V2,V4) | G13: Cov(V2,V5)
B14: Var 3 | C14: Cov(V3,V1) | D14: Cov(V3,V2) | E14: Var(V3) | F14: Cov(V3,V4) | G14: Cov(V3,V5)
B15: Var 4 | C15: Cov(V4,V1) | D15: Cov(V4,V2) | E15: Cov(V4,V3) | F15: Var(V4) | G15: Cov(V4,V5)
B16: Var 5 | C16: Cov(V5,V1) | D16: Cov(V5,V2) | E16: Cov(V5,V3) | F16: Cov(V5,V4) | G16: Var(V5)
B18: Notice that Cov(V1,V2) is the same as Cov(V2,V1), hence the symmetry.
B19: Positive Covariance: If the covariance is positive, it means that as one variable increases, the other variable tends to increase as well.
B20: Negative Covariance: If the covariance is negative, it means that as one variable increases, the other variable tends to decrease.
B21: Near Zero Covariance: If the covariance is close to zero, it means there's little to no linear relationship between the two variables. They tend to vary independently.
B23: This comparison is fundamental in:
B25: Understanding relationships: Identifying which variables tend to increase or decrease together.
B26: Feature selection in machine learning: Variables with very low covariance might be less useful in predicting each other.
B27: Econometrics and financial modeling: Understanding how economic indicators or asset prices move in relation to each other.
B28: Risk management: Assessing how different assets in a portfolio move together can help in diversification.
B30: Therefore, to avoid redundancy and make the table less cluttered, many software programs (and often statisticians presenting these tables) will only display either the upper triangular portion or the lower triangular portion of the matrix (excluding the diagonal, which represents variances, although sometimes included).

Sheet data
A1: CRIME_RATE | B1: AGE %(<1940) | C1: INDUSTRY | D1: NOX (ppm) | E1: DISTANCE FROM HW (MILES) | F1: TAX /$10,000 | G1: PTRATIO | H1: AVG_ROOM | I1: LSTAT | J1: AVG_PRICE IN K
A2: 4.3 | B2: 0.652 | C2: 2.31 | D2: 0.538 | E2: 1 | F2: 296 | G2: 15.3 | H2: 6.575 | I2: 4.98 | J2: 24 | L2: Understanding
A3: 4.31 | B3: 0.789 | C3: 7.07 | D3: 0.469 | E3: 2 | F3: 242 | G3: 17.8 | H3: 6.421 | I3: 9.14 | J3: 21.6 | L3: Lstat | M3: % of people in that area are poor and less educational qualities.ex:5 out of 100 people live there are lower status people
A4: 7.87 | B4: 0.611 | C4: 7.07 | D4: 0.469 | E4: 2 | F4: 242 | G4: 17.8 | H4: 7.185 | I4: 4.03 | J4: 34.7 | L4: Avg price | M4: avg price of houses in 1000k
A5: 6.47 | B5: 0.458 | C5: 2.18 | D5: 0.458 | E5: 3 | F5: 222 | G5: 18.7 | H5: 6.998 | I5: 2.94 | J5: 33.4 | L5: Pt ratio | M5: No.of students per teacher
A6: 5.24 | B6: 0.542 | C6: 2.18 | D6: 0.458 | E6: 3 | F6: 222 | G6: 18.7 | H6: 7.147 | I6: 5.33 | J6: 36.2 | L6: age | M6: Surity of houses that was built before 1940
A7: 9.75 | B7: 0.587 | C7: 2.18 | D7: 0.458 | E7: 3 | F7: 222 | G7: 18.7 | H7: 6.43 | I7: 5.21 | J7: 28.7 | L7: industry | M7: 2.3% of land in that area owned by big factories, warehouses,tech parks . Rather than clothing,groceries,restraunt shops
A8: 9.42 | B8: 0.666 | C8: 7.87 | D8: 0.524 | E8: 5 | F8: 311 | G8: 15.2 | H8: 6.012 | I8: 12.43 | J8: 22.9 | L8: nox | M8: air pollution in area caused by factories &vehicles
A9: 2.76 | B9: 0.961 | C9: 7.87 | D9: 0.524 | E9: 5 | F9: 311 | G9: 15.2 | H9: 6.172 | I9: 19.15 | J9: 27.1 | L9: age | M9: %of old houses (<1940) in that area
A10: 7.66 | B10: 1 | C10: 7.87 | D10: 0.524 | E10: 5 | F10: 311 | G10: 15.2 | H10: 5.631 | I10: 29.93 | J10: 16.5
A11: 1.12 | B11: 0.859 | C11: 7.87 | D11: 0.524 | E11: 5 | F11: 311 | G11: 15.2 | H11: 6.004 | I11: 17.1 | J11: 18.9
A12: 7.52 | B12: 0.943 | C12: 7.87 | D12: 0.524 | E12: 5 | F12: 311 | G12: 15.2 | H12: 6.377 | I12: 20.45 | J12: 15
A13: 1.55 | B13: 0.829 | C13: 7.87 | D13: 0.524 | E13: 5 | F13: 311 | G13: 15.2 | H13: 6.009 | I13: 13.27 | J13: 18.9
A14: 3.7 | B14: 0.39 | C14: 7.87 | D14: 0.524 | E14: 5 | F14: 311 | G14: 15.2 | H14: 5.889 | I14: 15.71 | J14: 21.7
A15: 7.14 | B15: 0.618 | C15: 8.14 | D15: 0.538 | E15: 4 | F15: 307 | G15: 21 | H15: 5.949 | I15: 8.26 | J15: 20.4
A16: 0.21 | B16: 0.845 | C16: 8.14 | D16: 0.538 | E16: 4 | F16: 307 | G16: 21 | H16: 6.096 | I16: 10.26 | J16: 18.2
A17: 8.6 | B17: 0.565 | C17: 8.14 | D17: 0.538 | E17: 4 | F17: 307 | G17: 21 | H17: 5.834 | I17: 8.47 | J17: 19.9
A18: 6.95 | B18: 0.293 | C18: 8.14 | D18: 0.538 | E18: 4 | F18: 307 | G18: 21 | H18: 5.935 | I18: 6.58 | J18: 23.1
A19: 0.8 | B19: 0.817 | C19: 8.14 | D19: 0.538 | E19: 4 | F19: 307 | G19: 21 | H19: 5.99 | I19: 14.67 | J19: 17.5
A20: 8.5 | B20: 0.366 | C20: 8.14 | D20: 0.538 | E20: 4 | F20: 307 | G20: 21 | H20: 5.456 | I20: 11.69 | J20: 20.2
A21: 5.53 | B21: 0.695 | C21: 8.14 | D21: 0.538 | E21: 4 | F21: 307 | G21: 21 | H21: 5.727 | I21: 11.28 | J21: 18.2
... A504: 0.46 | B504: 0.767 | C504: 11.93 | D504: 0.573 | E504: 1 | F504: 273 | G504: 21 | H504: 6.12 | I504: 9.08 | J504: 20.6
A505: 9.42 | B505: 0.91 | C505: 11.93 | D505: 0.573 | E505: 1 | F505: 273 | G505: 21 | H505: 6.976 | I505: 5.64 | J505: 23.9 | L505: =21+32+74+122+133+32+31+24+6+9+6+16 -> 506
A506: 6.94 | B506: 0.893 | C506: 11.93 | D506: 0.573 | E506: 1 | F506: 273 | G506: 21 | H506: 6.794 | I506: 6.48 | J506: 22
A507: 9.54 | B507: 0.808 | C507: 11.93 | D507: 0.573 | E507: 1 | F507: 273 | G507: 21 | H507: 6.03 | I507: 7.88 | J507: 11.9

Sheet regression data
A1: LSTAT | B1: Avg_price | C1: AVG_PRICE IN K | E1: LSTAT | F1: AVG_ROOM | G1: Avg_price | I1: CRIME_RATE | J1: AGE %(<1940) | K1: INDUSTRY | L1: NOX (ppm) | M1: DISTANCE FROM HW (MILES) | N1: TAX /$10,000 | O1: PTRATIO | P1: AVG_ROOM | Q1: LSTAT | R1: Avg_price
A2: 4.98 | B2: =C2*1000 -> 24000 | C2: 24 | E2: 4.98 | F2: 6.575 | G2: 24000 | I2: 4.3 | J2: 0.652 | K2: 2.31 | L2: 0.538 | M2: 1 | N2: 296 | O2: 15.3 | P2: 6.575 | Q2: 4.98 | R2: 24000
A3: 9.14 | B3: =C3*1000 -> 21600 | C3: 21.6 | E3: 9.14 | F3: 6.421 | G3: 21600 | I3: 4.31 | J3: 0.789 | K3: 7.07 | L3: 0.469 | M3: 2 | N3: 242 | O3: 17.8 | P3: 6.421 | Q3: 9.14 | R3: 21600
A4: 4.03 | B4: =C4*1000 -> 34700 | C4: 34.7 | E4: 4.03 | F4: 7.185 | G4: 34700 | I4: 7.87 | J4: 0.611 | K4: 7.07 | L4: 0.469 | M4: 2 | N4: 242 | O4: 17.8 | P4: 7.185 | Q4: 4.03 | R4: 34700
A5: 2.94 | B5: =C5*1000 -> 33400 | C5: 33.4 | E5: 2.94 | F5: 6.998 | G5: 33400 | I5: 6.47 | J5: 0.458 | K5: 2.18 | L5: 0.458 | M5: 3 | N5: 222 | O5: 18.7 | P5: 6.998 | Q5: 2.94 | R5: 33400
A6: 5.33 | B6: =C6*1000 -> 36200 | C6: 36.2 | E6: 5.33 | F6: 7.147 | G6: 36200 | I6: 5.24 | J6: 0.542 | K6: 2.18 | L6: 0.458 | M6: 3 | N6: 222 | O6: 18.7 | P6: 7.147 | Q6: 5.33 | R6: 36200
A7: 5.21 | B7: =C7*1000 -> 28700 | C7: 28.7 | E7: 5.21 | F7: 6.43 | G7: 28700 | I7: 9.75 | J7: 0.587 | K7: 2.18 | L7: 0.458 | M7: 3 | N7: 222 | O7: 18.7 | P7: 6.43 | Q7: 5.21 | R7: 28700
A8: 12.43 | B8: =C8*1000 -> 22900 | C8: 22.9 | E8: 12.43 | F8: 6.012 | G8: 22900 | I8: 9.42 | J8: 0.666 | K8: 7.87 | L8: 0.524 | M8: 5 | N8: 311 | O8: 15.2 | P8: 6.012 | Q8: 12.43 | R8: 22900
A9: 19.15 | B9: =C9*1000 -> 27100 | C9: 27.1 | E9: 19.15 | F9: 6.172 | G9: 27100 | I9: 2.76 | J9: 0.961 | K9: 7.87 | L9: 0.524 | M9: 5 | N9: 311 | O9: 15.2 | P9: 6.172 | Q9: 19.15 | R9: 27100
A10: 29.93 | B10: =C10*1000 -> 16500 | C10: 16.5 | E10: 29.93 | F10: 5.631 | G10: 16500 | I10: 7.66 | J10: 1 | K10: 7.87 | L10: 0.524 | M10: 5 | N10: 311 | O10: 15.2 | P10: 5.631 | Q10: 29.93 | R10: 16500
A11: 17.1 | B11: =C11*1000 -> 18900 | C11: 18.9 | E11: 17.1 | F11: 6.004 | G11: 18900 | I11: 1.12 | J11: 0.859 | K11: 7.87 | L11: 0.524 | M11: 5 | N11: 311 | O11: 15.2 | P11: 6.004 | Q11: 17.1 | R11: 18900
A12: 20.45 | B12: =C12*1000 -> 15000 | C12: 15 | E12: 20.45 | F12: 6.377 | G12: 15000 | I12: 7.52 | J12: 0.943 | K12: 7.87 | L12: 0.524 | M12: 5 | N12: 311 | O12: 15.2 | P12: 6.377 | Q12: 20.45 | R12: 15000
A13: 13.27 | B13: =C13*1000 -> 18900 | C13: 18.9 | E13: 13.27 | F13: 6.009 | G13: 18900 | I13: 1.55 | J13: 0.829 | K13: 7.87 | L13: 0.524 | M13: 5 | N13: 311 | O13: 15.2 | P13: 6.009 | Q13: 13.27 | R13: 18900
... A507: 7.88 | B507: =C507*1000 -> 11900 | C507: 11.9 | E507: 7.88 | F507: 6.03 | G507: 11900 | I507: 9.54 | J507: 0.808 | K507: 11.93 | L507: 0.573 | M507: 1 | N507: 273 | O507: 21 | P507: 6.03 | Q507: 7.88 | R507: 11900

Sheet descriptive stats
A1: CRIME_RATE | C1: AGE %(<1940) | E1: INDUSTRY | G1: NOX (ppm) | I1: DISTANCE FROM HW (MILES) | K1: TAX /$10,000 | M1: PTRATIO | O1: AVG_ROOM | Q1: LSTAT | S1: AVG_PRICE IN K
A2: Mean | B2: 4.8679842 | C2: Mean | D2: 0.68574901 | E2: Mean | F2: 11.136779 | G2: Mean | H2: 0.55469506 | I2: Mean | J2: 9.5494071 | K2: Mean | L2: 408.23715 | M2: Mean | N2: 18.455534 | O2: Mean | P2: 6.2846344 | Q2: Mean | R2: 12.653063 | S2: Mean | T2: 22532.806
A3: Standard Error | B3: 0.12983336 | C3: Standard Error | D3: 0.012513695 | E3: Standard Error | F3: 0.30497989 | G3: Standard Error | H3: 0.005151391 | I3: Standard Error | J3: 0.38708489 | K3: Standard Error | L3: 7.4923887 | M3: Standard Error | N3: 0.096243568 | O3: Standard Error | P3: 0.031235142 | Q3: Standard Error | R3: 0.31745891 | S3: Standard Error | T3: 408.86115
A4: Median | B4: 4.815 | C4: Median | D4: 0.775 | E4: Median | F4: 9.69 | G4: Median | H4: 0.538 | I4: Median | J4: 5 | K4: Median | L4: 330 | M4: Median | N4: 19.05 | O4: Median | P4: 6.2085 | Q4: Median | R4: 11.36 | S4: Median | T4: 21200
A5: Mode | B5: 3.43 | C5: Mode | D5: 1 | E5: Mode | F5: 18.1 | G5: Mode | H5: 0.538 | I5: Mode | J5: 24 | K5: Mode | L5: 666 | M5: Mode | N5: 20.2 | O5: Mode | P5: 5.713 | Q5: Mode | R5: 8.05 | S5: Mode | T5: 50000
A6: Standard Deviation | B6: 2.9205293 | C6: Standard Deviation | D6: 0.28148861 | E6: Standard Deviation | F6: 6.8603529 | G6: Standard Deviation | H6: 0.11587768 | I6: Standard Deviation | J6: 8.7072594 | K6: Standard Deviation | L6: 168.53712 | M6: Standard Deviation | N6: 2.1649455 | O6: Standard Deviation | P6: 0.70261714 | Q6: Standard Deviation | R6: 7.1410615 | S6: Standard Deviation | T6: 9197.1041
A7: Sample Variance | B7: 8.5294914 | C7: Sample Variance | D7: 0.07923584 | E7: Sample Variance | F7: 47.064442 | G7: Sample Variance | H7: 0.013427636 | I7: Sample Variance | J7: 75.816366 | K7: Sample Variance | L7: 28404.759 | M7: Sample Variance | N7: 4.6869891 | O7: Sample Variance | P7: 0.49367085 | Q7: Sample Variance | R7: 50.99476 | S7: Sample Variance | T7: 84586724
A8: Kurtosis | B8: -1.1876011 | C8: Kurtosis | D8: -0.96771559 | E8: Kurtosis | F8: -1.2335396 | G8: Kurtosis | H8: -0.064667133 | I8: Kurtosis | J8: -0.86723199 | K8: Kurtosis | L8: -1.142408 | M8: Kurtosis | N8: -0.28509138 | O8: Kurtosis | P8: 1.8915004 | Q8: Kurtosis | R8: 0.49323952 | S8: Kurtosis | T8: 1.4951969
A9: Skewness | B9: 0.025601287 | C9: Skewness | D9: -0.59896264 | E9: Skewness | F9: 0.29502157 | G9: Skewness | H9: 0.72930792 | I9: Skewness | J9: 1.0048146 | K9: Skewness | L9: 0.66995594 | M9: Skewness | N9: -0.80232493 | O9: Skewness | P9: 0.40361213 | Q9: Skewness | R9: 0.90646009 | S9: Skewness | T9: 1.1080984
A10: Range | B10: 9.95 | C10: Range | D10: 0.971 | E10: Range | F10: 27.28 | G10: Range | H10: 0.486 | I10: Range | J10: 23 | K10: Range | L10: 524 | M10: Range | N10: 9.4 | O10: Range | P10: 5.219 | Q10: Range | R10: 36.24 | S10: Range | T10: 45000
A11: Minimum | B11: 0.04 | C11: Minimum | D11: 0.029 | E11: Minimum | F11: 0.46 | G11: Minimum | H11: 0.385 | I11: Minimum | J11: 1 | K11: Minimum | L11: 187 | M11: Minimum | N11: 12.6 | O11: Minimum | P11: 3.561 | Q11: Minimum | R11: 1.73 | S11: Minimum | T11: 5000
A12: Maximum | B12: 9.99 | C12: Maximum | D12: 1 | E12: Maximum | F12: 27.74 | G12: Maximum | H12: 0.871 | I12: Maximum | J12: 24 | K12: Maximum | L12: 711 | M12: Maximum | N12: 22 | O12: Maximum | P12: 8.78 | Q12: Maximum | R12: 37.97 | S12: Maximum | T12: 50000
A13: Sum | B13: 2463.2 | C13: Sum | D13: 346.989 | E13: Sum | F13: 5635.21 | G13: Sum | H13: 280.6757 | I13: Sum | J13: 4832 | K13: Sum | L13: 206568 | M13: Sum | N13: 9338.5 | O13: Sum | P13: 3180.025 | Q13: Sum | R13: 6402.45 | S13: Sum | T13: 11401600
... A15: Confidence Level(99.0%) | B15: 0.33569712 | C15: Confidence Level(99.0%) | D15: 0.032355408 | E15: Confidence Level(99.0%) | F15: 0.78855593 | G15: Confidence Level(99.0%) | H15: 0.013319435 | I15: Confidence Level(99.0%) | J15: 1.0008466 | K15: Confidence Level(99.0%) | L15: 19.372319 | M15: Confidence Level(99.0%) | N15: 0.24884735 | O15: Confidence Level(99.0%) | P15: 0.080761576 | Q15: Confidence Level(99.0%) | R15: 0.82082168 | S15: Confidence Level(99.0%) | T15: 1057.1513
A17: Based on the stats of crime rate we can conclude the selected area wont cause any sesrious trouble for the property owners .because the records shows us most repeated rate is 3.43 which is very close to the aaverage rate of 4.86 . | C17: these stats shows us about 68% and above properties are built before 1940s . So the buyer can absolutely experience traditional lifestyles as well as classical art works and culture | E17: when we think about big factories and tech buildings, it is shown that only 11.1 % of the land were occupied by them on average . But with 18.1% of repeated value we can assure there must be plenty of job offers around here as well.so the buyer can have two benefit in one shot. | G17: Nitric oxide consideration matters most when we planned to move in sub_urbs area, we got 0.538 PPM on repeated value and 0.554 ppm as average . So compared to urban areas its far away from them. Hence we ensure each property will give you a fresh ,natural air to get refreshed everytime. | I17: A second thing to consider on moving to natural life was how we keep ourselves away from noisy highways, busy commercial areas, bustling streets,deafening horn sounds. These plot areas are 9.45miles far from highways on average. | K17: Absolutely paying taxes is pet peeve for everyone , but not here. The tax rate per $10,000 here is $408 which is comparitively lower than any other hotspot areas. Not $1000, Not $900 , only $711 is our highest tax rate here. | M17: As a parent, buyers don’t want to rumbling their mind with education for their child. here these area have 20.2 students per teacher ratio .If we talk about average it is 18.455. | O17: Mean value of 6.28 shows us that every property would have 6 rooms which engage there is plenty of spaces in each property . | Q17: if we think about neighbourhood here we | S17: Here the price range offers a buyers to select between vairous price category according to their budget . This are have as low as $5000 property and also $50,000 value property.

Sheet price range
A1: AVG_PRICE IN K | B1: AVG_PRICE
A2: 24 | B2: =A2*1000 -> 24000
A3: 21.6 | B3: =A3*1000 -> 21600
A4: 34.7 | B4: =A4*1000 -> 34700
A5: 33.4 | B5: =A5*1000 -> 33400
A6: 36.2 | B6: =A6*1000 -> 36200
A7: 28.7 | B7: =A7*1000 -> 28700
A8: 22.9 | B8: =A8*1000 -> 22900
A9: 27.1 | B9: =A9*1000 -> 27100
A10: 16.5 | B10: =A10*1000 -> 16500
A11: 18.9 | B11: =A11*1000 -> 18900
A12: 15 | B12: =A12*1000 -> 15000
A13: 18.9 | B13: =A13*1000 -> 18900
... A19: 17.5 | B19: =A19*1000 -> 17500
A20: 20.2 | B20: =A20*1000 -> 20200 | D20: Observation
A21: 18.2 | B21: =A21*1000 -> 18200 | D21: Based on the histogram ,329 properties are values between $13,000 and $25,000 out of 506 property totally. This conveys strongly that thers is wide variety of options to choose if buyers were budget concious.
A22: 13.6 | B22: =A22*1000 -> 13600
A23: 19.6 | B23: =A23*1000 -> 19600
A24: 15.2 | B24: =A24*1000 -> 15200
A25: 14.5 | B25: =A25*1000 -> 14500
A26: 15.6 | B26: =A26*1000 -> 15600
A27: 13.9 | B27: =A27*1000 -> 13900
A28: 16.6 | B28: =A28*1000 -> 16600
A29: 14.8 | B29: =A29*1000 -> 14800
A30: 18.4 | B30: =A30*1000 -> 18400
A31: 21 | B31: =A31*1000 -> 21000
A32: 12.7 | B32: =A32*1000 -> 12700
A33: 14.5 | B33: =A33*1000 -> 14500
... A507: 11.9 | B507: =A507*1000 -> 11900

Sheet covariance
B1: CRIME_RATE | C1: AGE %(<1940) | D1: INDUSTRY | E1: NOX (ppm) | F1: DISTANCE FROM HighWay (MILES) | G1: TAX /$10,000 | H1: PTRATIO | I1: AVG_ROOM | J1: LSTAT | K1: AVG_PRICE IN K
A2: CRIME_RATE | B2: =VARP(data!$A$2:$A$507) -> 8.5126347
A3: AGE %(<1940) | B3: 0.0057638814 | C3: =VARP(data!$B$2:$B$507) -> 0.079079247
A4: INDUSTRY | B4: -0.074977837 | C4: 1.2426783 | D4: =VARP(data!$C$2:$C$507) -> 46.97143
A5: NOX (ppm) | B5: 0.00069195644 | C5: 0.023812119 | D5: 0.60587394 | E5: =VARP(data!$D$2:$D$507) -> 0.013401099
A6: DISTANCE FROM HighWay (MILES) | B6: -0.19573044 | C6: 1.1154996 | D6: 35.479714 | E6: 0.61571022 | F6: =VARP(data!$E$2:$E$507) -> 75.666531
A7: TAX /$10,000 | B7: -7.7812611 | C7: 23.979417 | D7: 831.71333 | E7: 13.020502 | F7: 1333.1167 | G7: =VARP(data!$F$2:$F$507) -> 28348.624
A8: PTRATIO | B8: 0.080766095 | C8: 0.15905425 | D8: 5.6808548 | E8: 0.047303654 | F8: 8.7434025 | G8: 167.82082 | H8: =VARP(data!$G$2:$G$507) -> 4.6777263
A9: AVG_ROOM | B9: 0.054958611 | C9: -0.04742538 | D9: -1.8842254 | E9: -0.024554826 | F9: -1.2812774 | G9: -34.515101 | H9: -0.53969452 | I9: =VARP(data!$H$2:$H$507) -> 0.49269522
A10: LSTAT | B10: -0.85204877 | C10: 1.2083844 | D10: 29.521811 | E10: 0.48797987 | F10: 30.325392 | G10: 653.42062 | H10: 5.7713002 | I10: -3.073655 | J10: =VARP(data!$I$2:$I$507) -> 50.893979
A11: AVG_PRICE IN K | B11: 1.1561551 | C11: -0.97396153 | D11: -30.460505 | E11: -0.45451241 | F11: -30.50083 | G11: -724.82043 | H11: -10.090676 | I11: 4.4845656 | J11: -48.351792 | K11: =VARP(data!$J$2:$J$507) -> 84.419556
B13: observation | C13: If the covariance is positive, it means that as one variable increases, the other variable tends to increase as well.
C14: If the covariance is negative, it means that as one variable increases, the other variable tends to decreases.
C15: The digit count before the (.) indicates how strong the magnitude , which is how strongly the two variables moves in same directions either positive or negative
C17: Age vs Avg_price
C18: The covariance of these two variable is 1.156155064 ,a positive value . So if age decreases the price of the property increases as well.
C19: age vs avg_room
C20: Here -0.04742538 is the variance ,a negative value . If the age increases the tax rate tend to decrease and vice versa.
C21: Nox Vs Industry
B22: Small magnitude | C22: 0.605873942582293 is the covariance of these two variables. This positive value indicates if the industry area gets increased the quality of the air gets decreased
C23: Tax vs distance from Highway
B24: Strong magnitude | C24: 1333.11674139574 is positive value implies that if the property is far from the highway in the sense the tax rate will also increase
C25: Lstat vs avg_price
B26: Moderate magnitude | C26: -48.3517921932853 is a negative value , if the low status population increases the average price of the property tends to decreases

Sheet correlation
B1: CRIME_RATE | C1: AGE %(<1940) | D1: INDUSTRY | E1: NOX (ppm) | F1: DISTANCE FROM Highway (MILES) | G1: TAX /$10,000 | H1: PTRATIO | I1: AVG_ROOM | J1: LSTAT | K1: AVG_PRICE IN K
A2: CRIME_RATE | B2: 1
A3: AGE %(<1940) | B3: 0.0070250881 | C3: 1
A4: INDUSTRY | B4: -0.0037495921 | C4: 0.64477851 | D4: 1
A5: NOX (ppm) | B5: 0.0020486914 | C5: 0.7314701 | D5: 0.76365145 | E5: 1
A6: DISTANCE FROM Highway (MILES) | B6: -0.0077121323 | C6: 0.45602245 | D6: 0.59512927 | E6: 0.61144056 | F6: 1
A7: TAX /$10,000 | B7: -0.015839884 | C7: 0.50645559 | D7: 0.72076018 | E7: 0.6680232 | F7: 0.91022819 | G7: 1
A8: PTRATIO | B8: 0.012799107 | C8: 0.26151501 | D8: 0.38324756 | E8: 0.18893268 | F8: 0.46474118 | G8: 0.46085304 | H8: 1
A9: AVG_ROOM | B9: 0.026835802 | C9: -0.24026493 | D9: -0.39167585 | E9: -0.30218819 | F9: -0.20984667 | G9: -0.29204783 | H9: -0.35550149 | I9: 1
A10: LSTAT | B10: -0.04093542 | C10: 0.60233853 | D10: 0.60379972 | E10: 0.59087892 | F10: 0.48867633 | G10: 0.54399341 | H10: 0.37404432 | I10: -0.61380827 | J10: 1
A11: AVG_PRICE IN K | B11: 0.043128321 | C11: -0.37695457 | D11: -0.48372516 | E11: -0.42732077 | F11: -0.38162623 | G11: -0.46853593 | H11: -0.50778669 | I11: 0.69535995 | J11: -0.73766273 | K11: 1
A14: Top 3 postive correlated pairs
A15: Distance from highway Vs Tax rate per $10,000 | B15: 0.91022819 | C15: This suggests that as the distance from highways increases, property taxes tend to increase.
A16: Nox Vs Industry | B16: 0.76365145 | C16: This indicates a strong tendency for areas with more industrial land to have higher levels of nitrogen oxide pollution.
A17: Nox Vs Age % | B17: 0.7314701 | C17: This suggests that older properties tend to be located in areas with higher nitrogen oxide pollution.
A19: Top 3 negative correlated pairs
A20: Lstat Vs Avg_price | B20: -0.73766273 | C20: This indicates a strong tendency for areas with a higher percentage of lower-status population to have lower average house prices.
A21: Lstat Vs Avg_room | B21: -0.61380827 | C21: This suggests that properties with a higher average number of rooms tend to be located in areas with a lower percentage of lower-status population
A22: Ptratio Vs Avg_price | B22: -0.50778669 | C22: This indicates a moderate tendency for areas with a higher pupil-teacher ratio in schools to have lower average house prices.

Sheet regressions Q.5
A1: SUMMARY OUTPUT | R1: Answers
R2: Q.1 | S2: Summary output in terms of variance explained, coefficient value, Intercept, and the Residual plot
A3: Regression Statistics | S3: Variance | T3: - Approximately 54.41% of variation in Avg_price can be explained by Lstat. This indicates lstat is a moderatly strong prediction factor for avg_price
A4: Multiple R | B4: 0.73766273 | C4: 0.737662 indicates strong linear relationship between lstat and avg price.the closer it is to 1 or -1 ,the stronger the relation | S4: Coefficiant (Lstat) | T4: - For every 1% increase of Lstat, the Avg_price is predicted to increase by approximately $950. A opposite relationship
A5: R Square | B5: 0.5441463 | C5: 54% of avg price can be explained based on lstat | S5: Intercept | T5: - when Lstat is 0% the Avg_price predicted would approximately be 34553.84.
A6: Adjusted R Square | B6: 0.54324183 | S6: Residual Plot | T6: - This shows a plenty of scatter points randomly around a zero,which confirms a strong linear relationship
A7: Standard Error | B7: 6215.7604 | C7: Average magnitude by which the observed AVG_PRICE values deviate from the AVG_PRICE values predicted
A8: Observations | B8: 506 | C8: Observed data points | R8: Q.2 | S8: Is LSTAT variable significant for the analysis based on your model?
S9: Yeah, the Lstat variable is highly significant for the analysis. This is indicated by its p-value of 5.08e-88,[0.00000000000000000000000000000000000000000000000000000000000000000000000000000508)Since this P-value is much, much smaller than 0.05, this means that the LSTAT variable is statistically significant in explaining Avg_price. There is a real, non-zero relationship between LSTAT and Avg_price]
A10: ANOVA
B11: df | C11: SS | D11: MS | E11: F | F11: Significance F
A12: Regression | B12: 1 | C12: 2.3243914e+10 | D12: 2.3243914e+10 | E12: 601.61787 | F12: 5.0811034e-88
A13: Residual | B13: 504 | C13: 1.9472381e+10 | D13: 38635677
A14: Total | B14: 505 | C14: 4.2716295e+10
B16: Coefficients | C16: Standard Error | D16: t Stat | E16: P-value | F16: Lower 95% | G16: Upper 95% | H16: Lower 95.0% | I16: Upper 95.0%
A17: Intercept | B17: 34553.841 | C17: 562.62735 | D17: 61.415146 | E17: 3.7430809e-236 | F17: 33448.457 | G17: 35659.225 | H17: 33448.457 | I17: 35659.225
A18: LSTAT | B18: -950.04935 | C18: 38.733416 | D18: -24.5279 | E18: 5.0811034e-88 | F18: -1026.1482 | G18: -873.95051 | H18: -1026.1482 | I18: -873.95051
B19: 34553.84 is predicted avg price when lstat is 0
B20: -950.049 is lstat coefficient , indicates avg price decreases for1% of lstat value increases | C20: 38.73341621 is a precision of lstat coefficient estimate.smaller standard error means a more precise estimate | D20: - 24,5279 is test statistic for lstat coefficient.its absoute value is large,which suggest significance | E20: If P-value < α, the result is statistically significant. (Alpha=0.05). If P-value ≥α, the result is not statistically significant. P-values are your statistical gatekeepers. They tell you if the relationship you observe in your data is likely a genuine one, or just a fluke.
A22: RESIDUAL OUTPUT
A24: Observation | B24: Predicted Avg_price | C24: Residuals
A25: 1 | B25: 29822.595 | C25: -5822.5951 | D25: A negative residual indicates Predicted avg price is higher than actual avg price in our data.
A26: 2 | B26: 25870.39 | C26: -4270.3898
A27: 3 | B27: 30725.142 | C27: 3974.858 | D27: A positive residual indicated Predicted avg price is lower than actual avg price in our data
A28: 4 | B28: 31760.696 | C28: 1639.3042
A29: 5 | B29: 29490.078 | C29: 6709.9222
A30: 6 | B30: 29604.084 | C30: -904.08375
A31: 7 | B31: 22744.727 | C31: 155.27259
A32: 8 | B32: 16360.396 | C32: 10739.604
A33: 9 | B33: 6118.8637 | C33: 10381.136
A34: 10 | B34: 18307.997 | C34: 592.00307
A35: 11 | B35: 15125.332 | C35: -125.3316
A36: 12 | B36: 21946.686 | C36: -3046.686
A37: 13 | B37: 19628.566 | C37: 2071.4345
A38: 14 | B38: 26706.433 | C38: -6306.4332
A39: 15 | B39: 24806.335 | C39: -6606.3345
... A530: 506 | B530: 27067.452 | C530: -15167.452

Sheet Regression Q.6
A1: SUMMARY OUTPUT | R1: Write the Regression equation. If a new house in this locality has 7 rooms (on an average) and has a value of 20 for L-STAT, then what will be the value of AVG_PRICE? How does it compare to the company quoting a value of 30000 USD for this locality? Is the company Overcharging/ Undercharging?
R2: Predicted AVG_PRICE = -1358.27 + (-642.358 * LSTAT) + (5094.788 * AVG_ROOM)
A3: Regression Statistics | S3: Predicted avg_price | T3: =-1358.27 +(-642.358*0.02)+(5094.778*7) -> 34292.329
A4: Multiple R | B4: 0.7991005 | S4: company Quoted | T4: 30000
A5: R Square | B5: 0.63856161 | S5: Difference | T5: =T3-T4 -> 4292.3288
A6: Adjusted R Square | B6: 0.63712448 | T6: So based on the prediction , the company is undercharging by $4292.329
A7: Standard Error | B7: 5540.2574
A8: Observations | B8: 506 | R8: Is the performance of this model better than the previous model you built in Question 5? Compare in terms of adjusted R-square and explain
R9: Previous(LSTAT only): Adjusted R-square = 0.543241826 ( 54.32%)
A10: ANOVA | R10: Current (LSTAT + AVG_ROOM): Adjusted R-square = 0.637124 (63.71%)
B11: df | C11: SS | D11: MS | E11: F | F11: Significance F | R11: Here we can see that the current adjusted R value is higher than the previous table. So the performance of the current variables is better than the previous one.
A12: Regression | B12: 2 | C12: 2.7276986e+10 | D12: 1.3638493e+10 | E12: 444.33089 | F12: 7.0084553e-112 | G12: This p value is extremely smaller than 0.05. so both lstat and avg_room is Highly Statistically Significant. | R12: There is increase of 9.39 percentage indicates ,By adding another avg_room as independent variable ,additional 9.39% can be explained
A13: Residual | B13: 503 | C13: 1.5439309e+10 | D13: 30694452
A14: Total | B14: 505 | C14: 4.2716295e+10
B16: Coefficients | C16: Standard Error | D16: t Stat | E16: P-value | F16: Lower 95% | G16: Upper 95% | H16: Lower 95.0% | I16: Upper 95.0%
A17: Intercept | B17: -1358.2728 | C17: 3172.8278 | D17: -0.42809535 | E17: 0.66876494 | F17: -7591.9003 | G17: 4875.3547 | H17: -7591.9003 | I17: 4875.3547
A18: LSTAT | B18: -642.35833 | C18: 43.731465 | D18: -14.688699 | E18: 6.6693655e-41 | F18: -728.27717 | G18: -556.4395 | H18: -728.27717 | I18: -556.4395
A19: AVG_ROOM | B19: 5094.788 | C19: 444.4655 | D19: 11.46273 | E19: 3.4722576e-27 | F19: 4221.5504 | G19: 5968.0255 | H19: 4221.5504 | I19: 5968.0255
A23: RESIDUAL OUTPUT
A25: Observation | B25: Predicted Avg_price | C25: Residuals
A26: 1 | B26: 28941.014 | C26: -4941.0137
A27: 2 | B27: 25484.206 | C27: -3884.2057
A28: 3 | B28: 32659.075 | C28: 2040.9252
A29: 4 | B29: 32406.52 | C29: 993.48
A30: 5 | B30: 31630.407 | C30: 4569.593
A31: 6 | B31: 28054.527 | C31: 645.47299
A32: 7 | B32: 21287.078 | C32: 1612.9215
A33: 8 | B33: 17785.597 | C33: 9314.4035
A34: 9 | B34: 8104.6934 | C34: 8395.3066
A35: 10 | B35: 18246.507 | C35: 653.49327
A36: 11 | B36: 17994.962 | C36: -2994.9622
A37: 12 | B37: 20732.213 | C37: -1832.2131
... A531: 506 | B531: 24301.515 | C531: -12401.515

Sheet Regression Q.7
A1: SUMMARY OUTPUT | K1: Significant relation of each variable with Avg_price
K2: Variables | L2: Coefficient | M2: P-value | N2: Observation
A3: Regression Statistics | K3: NOX (ppm) | L3: -10321.163 | M3: 0.0082895692 | N3: For every 1 ppm increase in nitric oxides concentration, Avg_price is predicted to decrease by $10321.16. This makes sense as higher pollution typically lowers property values.The Pvalue is also less than 0.05 which indicates it is statiscallu significant
A4: Multiple R | B4: 0.8329961 | K4: PTRATIO | L4: -1074.5439 | M4: 6.4960451e-15 | N4: : For every one-unit increase in pupil-teacher ratio, Avg_price is predicted to decrease by $1074.54.This is a strong negative relationship. The schools might be located in a more population area . Which is more avg_price property area. The P value suggesting it is lower than 0.05 so it is statistically significant
A5: R Square | B5: 0.6938825 | K5: LSTAT | L5: -603.43485 | M5: 8.8851523e-27 | N5: For every 1 percentage increases in Lstat, Avg_price is predicted to decrease by $603.43. the P value is less than 0.05 indicates it is a statistically significant
A6: Adjusted R Square | B6: 0.68832795 | K6: TAX /$10,000 | L6: -14.393766 | M6: 0.00025304662 | N6: For every $10,000 increase in property tax, Avg_price is predicted to decrease by $14.39, the Pvalue indicates this is statistically significant relationship.
A7: Standard Error | B7: 5134.5221 | K7: CRIME_RATE | L7: 51.592995 | M7: 0.5109502 | N7: For every one-unit increase in CRIME_RATE, AVG_PRICE is predicted to increase by $51.59. P-value is 0.51095, which is greater than 0.05. Therefore, CRIME_RATE is not statistically significant.
A8: Observations | B8: 506 | K8: INDUSTRY | L8: 130.44329 | M8: 0.039276013 | N8: For every one-unit increase in the industry area per town, Avg_price is predicted to increase by $130.44. the P-value is less than 0.05 so Industry variable is statistically significant.
K9: DISTANCE FROM HW (MILES) | L9: 261.00123 | M9: 0.00013822297 | N9: For every one-mile increase in distance , Avg_price is predicted to increase by $261.00. the Pvalue is less than 0.05 so it is statistically significant.
A10: ANOVA | K10: AGE %(<1940) | L10: 3277.0431 | M10: 0.012665088 | N10: For every 1 percentage increase in the Age (< 1940), AVG_PRICE is predicted to increase by $3277.04.because the historical value of the property.the P-value is less than 0.05 so it is statistically significant.
B11: df | C11: SS | D11: MS | E11: F | F11: Significance F | K11: AVG_ROOM | L11: 4125.1304 | M11: 3.8990446e-19 | N11: For every one average room, Avg_price is predicted to increase by $4125.13, this is strong positive relationship. The P value is less than 0.05 indicates statistically significant.
A12: Regression | B12: 9 | C12: 2.964009e+10 | D12: 3.2933433e+09 | E12: 124.92143 | F12: 1.8884821e-121 | G12: This P-value is extremely small (virtually 0), much less than 0.05.all the included independent variables, is highly statistically significant. This means that at least one of the independent variables is a significant predictor of Avg_price.
A13: Residual | B13: 496 | C13: 1.3076205e+10 | D13: 26363317
A14: Total | B14: 505 | C14: 4.2716295e+10
K15: Intercept | L15: 29232.11 | M15: 2.5606739e-09 | N15: when all Independent variable is zero , the avg_price would be 29232.10991. the P-value is much smaller than 0.05. so the intercept is statistically significant.
B16: Coefficients | C16: Standard Error | D16: t Stat | E16: P-value | F16: Lower 95% | G16: Upper 95% | H16: Lower 95.0% | I16: Upper 95.0%
A17: Intercept | B17: 29232.11 | C17: 4816.7311 | D17: 6.068869 | E17: 2.5606739e-09 | F17: 19768.398 | G17: 38695.822 | H17: 19768.398 | I17: 38695.822 | K17: statistically significant variables | M17: Age, Industry, Nox, Distance from Highway, Tax per $10,000, Ptratio, Avg_Room, Lstat.
A18: CRIME_RATE | B18: 51.592995 | C18: 78.428632 | D18: 0.65783367 | E18: 0.5109502 | F18: -102.50031 | G18: 205.6863 | H18: -102.50031 | I18: 205.6863 | K18: statistically Not significant variables | M18: Crime _ Rate
A19: AGE %(<1940) | B19: 3277.0431 | C19: 1309.6918 | D19: 2.5021482 | E19: 0.012665088 | F19: 703.81523 | G19: 5850.2709 | H19: 703.81523 | I19: 5850.2709
A20: INDUSTRY | B20: 130.44329 | C20: 63.115153 | D20: 2.0667508 | E20: 0.039276013 | F20: 6.4372755 | G20: 254.44931 | H20: 6.4372755 | I20: 254.44931
A21: NOX (ppm) | B21: -10321.163 | C21: 3893.7684 | D21: -2.6506875 | E21: 0.0082895692 | F21: -17971.477 | G21: -2670.8495 | H21: -17971.477 | I21: -2670.8495
A22: DISTANCE FROM HW (MILES) | B22: 261.00123 | C22: 67.944964 | D22: 3.8413623 | E22: 0.00013822297 | F22: 127.5058 | G22: 394.49666 | H22: 127.5058 | I22: 394.49666
A23: TAX /$10,000 | B23: -14.393766 | C23: 3.9051215 | D23: -3.6858689 | E23: 0.00025304662 | F23: -22.066386 | G23: -6.7211462 | H23: -22.066386 | I23: -6.7211462
A24: PTRATIO | B24: -1074.5439 | C24: 133.59959 | D24: -8.0430174 | E24: 6.4960451e-15 | F24: -1337.0348 | G24: -812.05295 | H24: -1337.0348 | I24: -812.05295
A25: AVG_ROOM | B25: 4125.1304 | C25: 442.73847 | D25: 9.3173073 | E25: 3.8990446e-19 | F25: 3255.2563 | G25: 4995.0045 | H25: 3255.2563 | I25: 4995.0045
A26: LSTAT | B26: -603.43485 | C26: 53.075135 | D26: -11.369445 | E26: 8.8851523e-27 | F26: -707.71466 | G26: -499.15504 | H26: -707.71466 | I26: -499.15504
A30: RESIDUAL OUTPUT
A32: Observation | B32: Predicted Avg_price | C32: Residuals
A33: 1 | B33: 30016.682 | C33: -6016.6823
A34: 2 | B34: 27005.569 | C34: -5405.5694
A35: 3 | B35: 32841.079 | C35: 1858.9215
A36: 4 | B36: 31211.257 | C36: 2188.7425
A37: 5 | B37: 30595.505 | C37: 5604.4951
A38: 6 | B38: 28090.35 | C38: 609.65011
A39: 7 | B39: 25313.993 | C39: -2413.9928
A40: 8 | B40: 22542.05 | C40: 4557.9502
A41: 9 | B41: 14185.937 | C41: 2314.0631
A42: 10 | B42: 22667.198 | C42: -3767.1985
A43: 11 | B43: 22789.832 | C43: -7789.8321
A44: 12 | B44: 24922.853 | C44: -6022.8533
...

Sheet Regression Q.8
A1: SUMMARY OUTPUT
A3: Regression Statistics
A4: Multiple R | B4: 0.83283577 | L4: Q.1 - interpret output of this model
A5: R Square | B5: 0.69361543 | L5: Regression statistics | M5: Value | N5: Observation
A6: Adjusted R Square | B6: 0.68868368 | L6: Multiple R | M6: 0.83283577 | N6: A value close to 1 indicates a very strong positive linear relationship. Which is all independent variables are highly correlated with the average price.
A7: Standard Error | B7: 5131.5911 | L7: R Square | M7: 0.69361543 | N7: Approximately 69.36% of the variability in Avg_Price is explained by the 8 independent variables in this model
A8: Observations | B8: 506 | L8: Adjusted R Square | M8: 0.68868368 | N8: This is the R-squared value adjusted for the number of predictors.Approximately 68.87% of the variability in Avg_Price is explained,
L9: Standard Error | M9: 5131.5911 | N9: This is the typical difference (average error) between the actual Avg_Price values and the values predicted by your model. Here the difference is $5131.591 is the difference between ttwo of them.
A10: ANOVA | L10: Observations | M10: 506 | N10: Number of observed data for this regression table by model.
B11: df | C11: SS | D11: MS | E11: F | F11: Significance F
A12: Regression | B12: 8 | C12: 2.9628681e+10 | D12: 3.7035852e+09 | E12: 140.64304 | F12: 1.9109688e-122 | L12: Significance F | M12: 1.9109688e-122 | N12: This is the P-value for the overall regression model.Here we can conclude overall independent variables are highly statistically significant for Avg_Price in terms of it is lower than the 0.05.
A13: Residual | B13: 497 | C13: 1.3087614e+10 | D13: 26333227
A14: Total | B14: 505 | C14: 4.2716295e+10 | L14: Variables | M14: Values | N14: Observation | O14: P-value | P14: Are the Variable statistically significant?
L15: Intercept | M15: 29428.473 | N15: This is the predicted Avg_Price when all independent variables are zero. P-value 1.85E-09 is < 0.05, so the intercept is statistically significant. | O15: 1.85e-09 | P15: =IF(O15<0.05,"Yes","No") -> Yes
B16: Coefficients | C16: Standard Error | D16: t Stat | E16: P-value | F16: Lower 95% | G16: Upper 95% | H16: Lower 95.0% | I16: Upper 95.0% | L16: AGE %(<1940) | M16: 3293.496 | N16: For every 1 percentage increase in this variable, Avg_Price increases by $3293.50 | O16: 0.012162875 | P16: =IF(O16<0.05,"Yes","No") -> Yes
A17: Intercept | B17: 29428.473 | C17: 4804.7286 | D17: 6.1248982 | E17: 1.8459738e-09 | F17: 19988.39 | G17: 38868.557 | H17: 19988.39 | I17: 38868.557 | L17: INDUSTRY | M17: 130.71001 | N17: For every one-unit increase in industrial proportion, Avg_Price increases by $130.71. | O17: 0.038761669 | P17: =IF(O17<0.05,"Yes","No") -> Yes
A18: AGE %(<1940) | B18: 3293.496 | C18: 1308.7055 | D18: 2.516606 | E18: 0.012162875 | F18: 722.21873 | G18: 5864.7734 | H18: 722.21873 | I18: 5864.7734 | L18: NOX (ppm) | M18: -10272.705 | N18: For every 1 ppm increase in NOX, Avg_Price decreases by $10272.71 | O18: 0.0085457183 | P18: =IF(O18<0.05,"Yes","No") -> Yes
A19: INDUSTRY | B19: 130.71001 | C19: 63.077823 | D19: 2.0722023 | E19: 0.038761669 | F19: 6.7779423 | G19: 254.64207 | H19: 6.7779423 | I19: 254.64207 | L19: DISTANCE FROM HW (MILES) | M19: 261.50642 | N19: For every one-mile increase in distance , Avg_Price increases by $261.51 | O19: 0.00013288674 | P19: =IF(O19<0.05,"Yes","No") -> Yes
A20: NOX (ppm) | B20: -10272.705 | C20: 3890.8492 | D20: -2.6402218 | E20: 0.0085457183 | F20: -17917.246 | G20: -2628.1645 | H20: -17917.246 | I20: -2628.1645 | L20: TAX /$10,000 | M20: -14.452345 | N20: For every $10,000 increase in property tax, Avg_Price decreases by $14.45 | O20: 0.00023607181 | P20: =IF(O20<0.05,"Yes","No") -> Yes
A21: DISTANCE FROM HW (MILES) | B21: 261.50642 | C21: 67.901841 | D21: 3.851242 | E21: 0.00013288674 | F21: 128.09638 | G21: 394.91647 | H21: 128.09638 | I21: 394.91647 | L21: PTRATIO | M21: -1071.7025 | N21: For every one-unit increase in pupil-teacher ratio, Avg_Price decreases by $1071.70 | O21: 7.0825099e-15 | P21: =IF(O21<0.05,"Yes","No") -> Yes
A22: TAX /$10,000 | B22: -14.452345 | C22: 3.9018775 | D22: -3.7039464 | E22: 0.00023607181 | F22: -22.118553 | G22: -6.7861367 | H22: -22.118553 | I22: -6.7861367 | L22: AVG_ROOM | M22: 4125.469 | N22: For every one additional average room, Average Price increases by $4125.47 | O22: 3.6896908e-19 | P22: =IF(O22<0.05,"Yes","No") -> Yes
A23: PTRATIO | B23: -1071.7025 | C23: 133.45353 | D23: -8.0305293 | E23: 7.0825099e-15 | F23: -1333.9051 | G23: -809.49984 | H23: -1333.9051 | I23: -809.49984 | L23: LSTAT | M23: -605.15928 | N23: For every 1 percentage point increase in LSTAT, Avg_price decreases by $605.16. | O23: 5.418443e-27 | P23: =IF(O23<0.05,"Yes","No") -> Yes
A24: AVG_ROOM | B24: 4125.469 | C24: 442.48544 | D24: 9.3234005 | E24: 3.6896908e-19 | F24: 3256.0963 | G24: 4994.8416 | H24: 3256.0963 | I24: 4994.8416
A25: LSTAT | B25: -605.15928 | C25: 52.9801 | D25: -11.422388 | E25: 5.418443e-27 | F25: -709.25186 | G25: -501.0667 | H25: -709.25186 | I25: -501.0667
L26: Q.2 -Compare the adjusted R-square value of this model with the model in the previous question, which model performs better according to the value of adjusted R-square?
L28: Previous Model | M28: 0.68832795 | N28: Aprx -68.83%
A29: RESIDUAL OUTPUT | L29: Current Model | M29: 0.68868368 | N29: Aprx-68.87%
L30: Observation | M30: The current model performs slightly better than the previous model .This confirms , Removing Crime_Rate which is not statistically significant actually make sense and improves models explanatory efficency slightly.
A31: Observation | B31: Predicted Avg_price | C31: Residuals
A32: 1 | B32: 30048.887 | C32: -6048.8873 | L32: Q.3 - Sort the values of the Coefficients in ascending order. What will happen to the average price if the value of NOX is more in a locality in this town?
A33: 2 | B33: 27040.985 | C33: -5440.9846
A34: 3 | B34: 32698.965 | C34: 2001.0355 | L34: Variables | M34: Values
A35: 4 | B35: 31143.069 | C35: 2256.9305 | L35: NOX (ppm) | M35: -10272.705 | N35: The coefficient for NOX (ppm) is -10272.71. This is the most negative coefficient among all the variables.For every 1 ppm increase in NOX, the Avg_Price is expected to decrease by approximately $10,272.71. which is Strong Negative factor.
A36: 5 | B36: 30588.087 | C36: 5611.9127 | L36: PTRATIO | M36: -1071.7025
A37: 6 | B37: 27850.953 | C37: 849.04746 | L37: LSTAT | M37: -605.15928
A38: 7 | B38: 25070.897 | C38: -2170.8969 | L38: TAX /$10,000 | M38: -14.452345
A39: 8 | B39: 22635.883 | C39: 4464.1171 | L39: INDUSTRY | M39: 130.71001
A40: 9 | B40: 14008.833 | C40: 2491.1666 | L40: DISTANCE FROM HW (MILES) | M40: 261.50642
A41: 10 | B41: 22847.444 | C41: -3947.444 | L41: AGE %(<1940) | M41: 3293.496
A42: 11 | B42: 22635.614 | C42: -7635.614 | L42: AVG_ROOM | M42: 4125.469
...

Sheet data Ref
A1: CRIME_RATE | B1: AGE %(<1940) | C1: INDUSTRY | D1: NOX | E1: DISTANCE FROM HW (MILES) | F1: TAX /$10,000 | G1: PTRATIO | H1: AVG_ROOM | I1: LSTAT | J1: AVG_PRICE IN K
A2: 6.32 | B2: 0.652 | C2: 2.31 | D2: 0.538 | E2: 1 | F2: 296 | G2: 15.3 | H2: 6.575 | I2: 4.98 | J2: 24
A3: 4.31 | B3: 0.789 | C3: 7.07 | D3: 0.469 | E3: 2 | F3: 242 | G3: 17.8 | H3: 6.421 | I3: 9.14 | J3: 21.6
A4: 7.87 | B4: 0.611 | C4: 7.07 | D4: 0.469 | E4: 2 | F4: 242 | G4: 17.8 | H4: 7.185 | I4: 4.03 | J4: 34.7
A5: 6.47 | B5: 0.458 | C5: 2.18 | D5: 0.458 | E5: 3 | F5: 222 | G5: 18.7 | H5: 6.998 | I5: 2.94 | J5: 33.4
A6: 5.24 | B6: 0.542 | C6: 2.18 | D6: 0.458 | E6: 3 | F6: 222 | G6: 18.7 | H6: 7.147 | I6: 5.33 | J6: 36.2
A7: 9.75 | B7: 0.587 | C7: 2.18 | D7: 0.458 | E7: 3 | F7: 222 | G7: 18.7 | H7: 6.43 | I7: 5.21 | J7: 28.7
A8: 9.42 | B8: 0.666 | C8: 7.87 | D8: 0.524 | E8: 5 | F8: 311 | G8: 15.2 | H8: 6.012 | I8: 12.43 | J8: 22.9
A9: 2.76 | B9: 0.961 | C9: 7.87 | D9: 0.524 | E9: 5 | F9: 311 | G9: 15.2 | H9: 6.172 | I9: 19.15 | J9: 27.1
A10: 7.66 | B10: 1 | C10: 7.87 | D10: 0.524 | E10: 5 | F10: 311 | G10: 15.2 | H10: 5.631 | I10: 29.93 | J10: 16.5
A11: 1.12 | B11: 0.859 | C11: 7.87 | D11: 0.524 | E11: 5 | F11: 311 | G11: 15.2 | H11: 6.004 | I11: 17.1 | J11: 18.9
A12: 7.52 | B12: 0.943 | C12: 7.87 | D12: 0.524 | E12: 5 | F12: 311 | G12: 15.2 | H12: 6.377 | I12: 20.45 | J12: 15
A13: 1.55 | B13: 0.829 | C13: 7.87 | D13: 0.524 | E13: 5 | F13: 311 | G13: 15.2 | H13: 6.009 | I13: 13.27 | J13: 18.9
... A507: 9.54 | B507: 0.808 | C507: 11.93 | D507: 0.573 | E507: 1 | F507: 273 | G507: 21 | H507: 6.03 | I507: 7.88 | J507: 11.9
